<?xml version="1.0" encoding="UTF-8"?>
<!-- Generated by org.testng.reporters.JUnitReportReporter -->
<testsuite skipped="3" hostname="IVF111" name="com_Milan_Test.WAllergiesTest" tests="9" failures="1" timestamp="11 Jul 2018 21:22:07 GMT" time="580.904" errors="0">
  <testcase name="AllergySelectionTest" time="57.717" classname="com_Milan_Test.WAllergiesTest">
    <failure type="java.lang.AssertionError" message="expected [Record updated successfully!] but found [Record saved successfully!]">
      <![CDATA[java.lang.AssertionError: expected [Record updated successfully!] but found [Record saved successfully!]
	at org.testng.Assert.fail(Assert.java:93)
	at org.testng.Assert.failNotEquals(Assert.java:512)
	at org.testng.Assert.assertEqualsImpl(Assert.java:134)
	at org.testng.Assert.assertEquals(Assert.java:115)
	at org.testng.Assert.assertEquals(Assert.java:189)
	at org.testng.Assert.assertEquals(Assert.java:199)
	at com_Milan_Test.WAllergiesTest.AllergySelectionTest(WAllergiesTest.java:105)
	at sun.reflect.NativeMethodAccessorImpl.invoke0(Native Method)
	at sun.reflect.NativeMethodAccessorImpl.invoke(Unknown Source)
	at sun.reflect.DelegatingMethodAccessorImpl.invoke(Unknown Source)
	at java.lang.reflect.Method.invoke(Unknown Source)
	at org.testng.internal.MethodInvocationHelper.invokeMethod(MethodInvocationHelper.java:108)
	at org.testng.internal.Invoker.invokeMethod(Invoker.java:661)
	at org.testng.internal.Invoker.retryFailed(Invoker.java:1014)
	at org.testng.internal.Invoker.invokeTestMethods(Invoker.java:1215)
	at org.testng.internal.TestMethodWorker.invokeTestMethods(TestMethodWorker.java:126)
	at org.testng.internal.TestMethodWorker.run(TestMethodWorker.java:109)
	at org.testng.TestRunner.privateRun(TestRunner.java:744)
	at org.testng.TestRunner.run(TestRunner.java:602)
	at org.testng.SuiteRunner.runTest(SuiteRunner.java:380)
	at org.testng.SuiteRunner.access$000(SuiteRunner.java:39)
	at org.testng.SuiteRunner$SuiteWorker.run(SuiteRunner.java:414)
	at org.testng.internal.thread.ThreadUtil$1.call(ThreadUtil.java:52)
	at java.util.concurrent.FutureTask.run(Unknown Source)
	at java.util.concurrent.ThreadPoolExecutor.runWorker(Unknown Source)
	at java.util.concurrent.ThreadPoolExecutor$Worker.run(Unknown Source)
	at java.lang.Thread.run(Unknown Source)
]]>
    </failure>
  </testcase> <!-- AllergySelectionTest -->
  <testcase name="AllergySelectionTest" time="153.600" classname="com_Milan_Test.WAllergiesTest">
    <skipped/>
  </testcase> <!-- AllergySelectionTest -->
  <testcase name="AllergySelectionTest" time="58.437" classname="com_Milan_Test.WAllergiesTest">
    <skipped/>
  </testcase> <!-- AllergySelectionTest -->
  <testcase name="AllergySelectionTest" time="57.068" classname="com_Milan_Test.WAllergiesTest">
    <skipped/>
  </testcase> <!-- AllergySelectionTest -->
  <testcase name="FoodAllergyvalidationTest" time="50.062" classname="com_Milan_Test.WAllergiesTest"/>
  <testcase name="AddNewAllergiesTest" time="51.797" classname="com_Milan_Test.WAllergiesTest"/>
  <testcase name="AllergiesOnDashboardforNewPatientTest" time="49.729" classname="com_Milan_Test.WAllergiesTest"/>
  <testcase name="OptionSelectedOnAllergyCurrentStstusTest" time="52.387" classname="com_Milan_Test.WAllergiesTest"/>
  <testcase name="ExistingPatientDrugAllergyTypeTest" time="50.107" classname="com_Milan_Test.WAllergiesTest"/>
</testsuite> <!-- com_Milan_Test.WAllergiesTest -->
